Workbook

Sheet Read Me
A1: Trade Stock List — Read Me
A2: This workbook is the master list for the class stock website. Each trade button on the site will show the rows from the Stocks tab whose Status is 'Include'.
A4: What to edit
A5: • Stocks tab: every column is editable. Light-yellow cells are yours. Use the dropdowns for Category, Role and Status.
A6: • Categories tab: edit the button label, icon, description, button order and benchmark ETF. The count columns are formulas — leave them alone.
A7: • To add a stock: add a new row at the bottom of the Stocks table (ticker, company, category, role, status, what they do, student hook).
A8: • Example of a complete row: AXON | Axon Enterprise | Law Enforcement | (blank) | Tools/Supplies | Include | Tasers, body cameras… | Body cams went from rare to standard…
A10: Status meanings
A11: • Include — shows on the website.
A12: • Optional — ready to go, but needs your (or admin's) decision first.
A13: • Alternate — a good swap-in if a list feels stale or a company changes.
A14: • Review — something changed (merger, ticker change, delisting); check before using.
... A33: Free data sources don't provide analyst price targets. Copy them from Yahoo Finance into column J (and the date into K) whenever you like; the nightly update picks them up. Blank cells show as 'Not entered' on the site.

Sheet Stocks
A1: Ticker | B1: Company | C1: Category | D1: Also In | E1: Role | F1: Status | G1: What They Do | H1: Student Hook | I1: Teacher Notes | J1: 1y Target Est | K1: Target As Of
A2: AXON | B2: Axon Enterprise | C2: Law Enforcement | E2: Tools/Supplies | F2: Include | G2: Tasers, body cameras and Evidence.com digital-evidence software. | H2: Body cams went from rare to standard. How did that show up in Axon's revenue and stock?
A3: MSI | B3: Motorola Solutions | C3: Law Enforcement | E3: Tools/Supplies | F3: Include | G3: Police and fire radios, 911 dispatch and command-center software. | H3: Who pays for the radio on every officer's belt, and how often does it get replaced?
A4: FSS | B4: Federal Signal | C4: Law Enforcement | E4: Tools/Supplies | F4: Include | G4: Emergency light bars and sirens; also street sweepers and vacuum trucks. | H4: A smaller company that's on almost every cruiser. Do smaller stocks move more day to day?
A5: SWBI | B5: Smith & Wesson Brands | C5: Law Enforcement | E5: Tools/Supplies | F5: Include | G5: Handguns and rifles for law enforcement and civilian buyers. | H5: Watch how this stock reacts to news headlines and elections. | I5: Included per teacher decision (Oct 29, 2026).
A6: RGR | B6: Sturm, Ruger & Co. | C6: Law Enforcement | E6: Tools/Supplies | F6: Optional | G6: Firearms maker (Ruger, Marlin). | H6: Compare RGR and SWBI: same industry, same reactions? | I6: Not included; SWBI chosen as the one firearms stock.
A7: PG | B7: Procter & Gamble | C7: Cosmetology | E7: Giant | F7: Include | G7: Pantene, Head & Shoulders, Olay and many household brands; a classic steady dividend stock. | H7: Compare PG's daily moves to e.l.f.'s. Why is one so much calmer?
A8: EL | B8: Estée Lauder | C8: Cosmetology | E8: Tools/Supplies | F8: Include | G8: MAC, Clinique, Aveda; Aveda also runs cosmetology schools. | H8: Pull up EL's 5-year chart. What story does it tell?
A9: SBH | B9: Sally Beauty Holdings | C9: Cosmetology | E9: Distributor | F9: Include | G9: Sally Beauty stores plus CosmoProf, the supplier for licensed professionals. | H9: Once you're licensed, where will you buy your supplies?
A10: ULTA | B10: Ulta Beauty | C10: Cosmetology | E10: Employer | F10: Include | G10: Beauty retailer with in-store salons that hire licensed stylists. | H10: Retail plus salon services: which part of the business matters more?
A11: ELF | B11: e.l.f. Beauty | C11: Cosmetology | E11: Wildcard | F11: Include | G11: Low-price cosmetics popular with teens; a volatile, fast-moving stock. | H11: Can a social-media trend show up in a stock price?
A12: CARR | B12: Carrier Global | C12: HVAC | E12: Giant | F12: Include | G12: Residential and commercial heating and cooling; Willis Carrier invented modern air conditioning. | H12: AC was invented in 1902. Is this company still growing?
A13: TT | B13: Trane Technologies | C13: HVAC | E13: Tools/Supplies | F13: Include | G13: Commercial and residential HVAC systems. | H13: Trane vs. Carrier: same industry, different charts?
A14: LII | B14: Lennox International | C14: HVAC | E14: Tools/Supplies | F14: Include | G14: Residential furnaces, AC and heat pumps sold directly to contractors. | H14: Does a hot summer or a cold winter show up in Lennox's results?
A15: WSO | B15: Watsco | C15: HVAC | E15: Distributor | F15: Include | G15: Largest HVAC/R equipment distributor in North America. | H15: Where does a tech actually pick up the unit before an install?
A16: FIX | B16: Comfort Systems USA | C16: HVAC | D16: Electrical | E16: Employer | F16: Include | G16: Mechanical and electrical contractor; data-center projects have driven big growth. | H16: Data centers need huge amounts of cooling. Who does the install work?
A17: MSFT | B17: Microsoft | C17: P-Tech / IT | E17: Giant | F17: Include | G17: Windows, Office, Azure cloud and widely used IT certifications. | H17: Which Microsoft products did you use today?
A18: CSCO | B18: Cisco Systems | C18: P-Tech / IT | E18: Tools/Supplies | F18: Include | G18: Networking hardware and the CCNA certification. | H18: Most networks you've used run through Cisco gear. Is it a growth stock or a steady one?
A19: NVDA | B19: Nvidia | C19: P-Tech / IT | E19: Tools/Supplies | F19: Include | G19: Graphics and AI chips used in data centers and gaming. | H19: Look at NVDA's 5-year chart. What changed?
A20: IBM | B20: IBM | C20: P-Tech / IT | E20: Employer | F20: Include | G20: Hybrid cloud, AI and mainframes; IBM helped create the P-TECH school model. | H20: The company behind P-TECH: what does it actually sell today?
A21: CRWD | B21: CrowdStrike | C21: P-Tech / IT | E21: Wildcard | F21: Include | G21: Cybersecurity software protecting company computers and networks. | H21: Look up July 2024. What did one bad software update do to the stock? | I21: Great internet-sleuthing case study.
A22: CAT | B22: Caterpillar | C22: Engineering / Manufacturing | E22: Giant | F22: Include | G22: Heavy construction and mining equipment, engines and generators. | H22: CAT is often called an economic bellwether. Why?
A23: ROK | B23: Rockwell Automation | C23: Engineering / Manufacturing | E23: Tools/Supplies | F23: Include | G23: Factory automation and Allen-Bradley PLCs. | H23: Ever programmed an Allen-Bradley PLC? That's Rockwell.
A24: LECO | B24: Lincoln Electric | C24: Engineering / Manufacturing | E24: Tools/Supplies | F24: Include | G24: Welding machines, wire and consumables. | H24: What brand is the welder in your shop?
A25: FAST | B25: Fastenal | C25: Engineering / Manufacturing | E25: Distributor | F25: Include | G25: Industrial and construction supplies, including on-site vending machines at factories. | H25: How does a company that sells nuts and bolts become a big stock?
A26: DE | B26: Deere & Co. | C26: Engineering / Manufacturing | E26: Employer | F26: Include | G26: Agricultural and construction machinery; a major U.S. manufacturing employer. | H26: How might crop prices affect tractor sales?
A27: GE | B27: GE Aerospace | C27: Engineering / Manufacturing | E27: Giant | F27: Alternate | G27: Jet engines for commercial and military aircraft. | H27: GE used to make light bulbs and fridges. What happened?
A28: HD | B28: Home Depot | C28: Carpentry | D28: Electrical; HVAC | E28: Giant | F28: Include | G28: Largest home-improvement retailer, with a big pro-contractor business. | H28: Does a housing slowdown show up in HD's chart?
A29: LOW | B29: Lowe's | C29: Carpentry | E29: Distributor | F29: Include | G29: Second-largest home-improvement retailer. | H29: Head-to-head: HD vs. LOW over 1 year and 5 years.
A30: WY | B30: Weyerhaeuser | C30: Carpentry | E30: Tools/Supplies | F30: Include | G30: Timberland owner and lumber/wood-products maker. | H30: Track lumber prices next to WY's stock. Do they move together?
A31: SWK | B31: Stanley Black & Decker | C31: Carpentry | E31: Tools/Supplies | F31: Include | G31: DeWalt, Craftsman and Stanley tools. | H31: What brand is your drill?
A32: TREX | B32: Trex Company | C32: Carpentry | E32: Wildcard | F32: Include | G32: Composite decking made from recycled materials. | H32: Decks are a summer project. Is there a seasonal pattern?
A33: DHI | B33: D.R. Horton | C33: Carpentry | E33: Employer | F33: Alternate | G33: Largest U.S. homebuilder by volume. | H33: How do mortgage rates affect homebuilders?
A34: F | B34: Ford Motor | C34: Auto-Tech / AutoBody | D34: Law Enforcement | E34: Giant | F34: Include | G34: Trucks, cars and EVs; builds the Police Interceptor Utility. | H34: F-150 vs. EVs: where is Ford's money coming from?
A35: TSLA | B35: Tesla | C35: Auto-Tech / AutoBody | E35: Wildcard | F35: Include | G35: Electric vehicles, batteries and charging; EVs need different service skills. | H35: Gas vs. EV: compare F and TSLA over 5 years.
A36: SNA | B36: Snap-on | C36: Auto-Tech / AutoBody | E36: Tools/Supplies | F36: Include | G36: The tool truck: hand tools, diagnostic scanners and tool financing. | H36: Snap-on also lends money to techs for tools. How does that affect the business?
A37: ORLY | B37: O'Reilly Automotive | C37: Auto-Tech / AutoBody | E37: Distributor | F37: Include | G37: Auto-parts stores serving DIY customers and professional shops. | H37: More older cars on the road means more repairs. Good for O'Reilly?
A38: PPG | B38: PPG Industries | C38: Auto-Tech / AutoBody | E38: Tools/Supplies | F38: Include | G38: Paints and coatings, including automotive refinish paint for body shops. | H38: Body-shop paint is only part of PPG. What else do they make?
A39: GM | B39: General Motors | C39: Auto-Tech / AutoBody | E39: Giant | F39: Alternate | G39: Chevrolet, GMC, Buick, Cadillac. | H39: Ford vs. GM: which has done better lately?
A40: CPRT | B40: Copart | C40: Auto-Tech / AutoBody | E40: Distributor | F40: Alternate | G40: Online auctions for wrecked and salvage vehicles. | H40: Where does a totaled car go after the insurance claim?
...

Sheet Categories
A1: Button Order | B1: Button Label | C1: Icon | D1: Button Description | E1: Sector Benchmark | F1: Stocks Shown (Include) | G1: Also-In Badges | H1: Optional / Alternate
A2: 1 | B2: Law Enforcement | C2: 🚔 | D2: Gear, radios and vehicles behind policing. (Most police employers are governments, so there's no 'employer' stock here.) | E2: SPY | F2: =COUNTIFS(Stocks!$C$2:$C$106,B2,Stocks!$F$2:$F$106,"Include") | G2: =COUNTIFS(Stocks!$D$2:$D$106,"*"&B2&"*",Stocks!$F$2:$F$106,"Include") | H2: =COUNTIFS(Stocks!$C$2:$C$106,B2,Stocks!$F$2:$F$106,"Optional")+COUNTIFS(Stocks!$C$2:$C$106,B2,Stocks!$F$2:$F$106,"Alternate")
A3: 2 | B3: Cosmetology | C3: 💇 | D3: Product makers, supply stores and salon chains. | E3: XLP | F3: =COUNTIFS(Stocks!$C$2:$C$106,B3,Stocks!$F$2:$F$106,"Include") | G3: =COUNTIFS(Stocks!$D$2:$D$106,"*"&B3&"*",Stocks!$F$2:$F$106,"Include") | H3: =COUNTIFS(Stocks!$C$2:$C$106,B3,Stocks!$F$2:$F$106,"Optional")+COUNTIFS(Stocks!$C$2:$C$106,B3,Stocks!$F$2:$F$106,"Alternate")
A4: 3 | B4: HVAC | C4: ❄️ | D4: Equipment makers, the distributor techs buy from, and a contractor that hires. | E4: XLI | F4: =COUNTIFS(Stocks!$C$2:$C$106,B4,Stocks!$F$2:$F$106,"Include") | G4: =COUNTIFS(Stocks!$D$2:$D$106,"*"&B4&"*",Stocks!$F$2:$F$106,"Include") | H4: =COUNTIFS(Stocks!$C$2:$C$106,B4,Stocks!$F$2:$F$106,"Optional")+COUNTIFS(Stocks!$C$2:$C$106,B4,Stocks!$F$2:$F$106,"Alternate")
A5: 4 | B5: P-Tech / IT | C5: 💻 | D5: Software, networking, chips and cybersecurity. | E5: XLK | F5: =COUNTIFS(Stocks!$C$2:$C$106,B5,Stocks!$F$2:$F$106,"Include") | G5: =COUNTIFS(Stocks!$D$2:$D$106,"*"&B5&"*",Stocks!$F$2:$F$106,"Include") | H5: =COUNTIFS(Stocks!$C$2:$C$106,B5,Stocks!$F$2:$F$106,"Optional")+COUNTIFS(Stocks!$C$2:$C$106,B5,Stocks!$F$2:$F$106,"Alternate")
A6: 5 | B6: Engineering / Manufacturing | C6: ⚙️ | D6: Heavy equipment, automation, welding and industrial supply. | E6: XLI | F6: =COUNTIFS(Stocks!$C$2:$C$106,B6,Stocks!$F$2:$F$106,"Include") | G6: =COUNTIFS(Stocks!$D$2:$D$106,"*"&B6&"*",Stocks!$F$2:$F$106,"Include") | H6: =COUNTIFS(Stocks!$C$2:$C$106,B6,Stocks!$F$2:$F$106,"Optional")+COUNTIFS(Stocks!$C$2:$C$106,B6,Stocks!$F$2:$F$106,"Alternate")
A7: 6 | B7: Carpentry | C7: 🪚 | D7: Lumber, tools, home-improvement retail and building products. | E7: XHB | F7: =COUNTIFS(Stocks!$C$2:$C$106,B7,Stocks!$F$2:$F$106,"Include") | G7: =COUNTIFS(Stocks!$D$2:$D$106,"*"&B7&"*",Stocks!$F$2:$F$106,"Include") | H7: =COUNTIFS(Stocks!$C$2:$C$106,B7,Stocks!$F$2:$F$106,"Optional")+COUNTIFS(Stocks!$C$2:$C$106,B7,Stocks!$F$2:$F$106,"Alternate")
A8: 7 | B8: Auto-Tech / AutoBody | C8: 🚗 | D8: Automakers, tools, parts and refinish paint. | E8: XLY | F8: =COUNTIFS(Stocks!$C$2:$C$106,B8,Stocks!$F$2:$F$106,"Include") | G8: =COUNTIFS(Stocks!$D$2:$D$106,"*"&B8&"*",Stocks!$F$2:$F$106,"Include") | H8: =COUNTIFS(Stocks!$C$2:$C$106,B8,Stocks!$F$2:$F$106,"Optional")+COUNTIFS(Stocks!$C$2:$C$106,B8,Stocks!$F$2:$F$106,"Alternate")
A9: 8 | B9: Electrical | C9: ⚡ | D9: Power equipment, wiring, generators and grid work. | E9: XLI | F9: =COUNTIFS(Stocks!$C$2:$C$106,B9,Stocks!$F$2:$F$106,"Include") | G9: =COUNTIFS(Stocks!$D$2:$D$106,"*"&B9&"*",Stocks!$F$2:$F$106,"Include") | H9: =COUNTIFS(Stocks!$C$2:$C$106,B9,Stocks!$F$2:$F$106,"Optional")+COUNTIFS(Stocks!$C$2:$C$106,B9,Stocks!$F$2:$F$106,"Alternate")
B10: Total | F10: =SUM(F2:F9) | G10: =SUM(G2:G9) | H10: =SUM(H2:H9)
B12: Site-wide benchmark | D12: SPY (S&P 500) — shown on every trade page for comparison.
B13: Unique tickers (all statuses) | D13: =SUMPRODUCT((Stocks!$A$2:$A$106<>"")/COUNTIF(Stocks!$A$2:$A$106,Stocks!$A$2:$A$106&""))

Sheet Lists
A1: Roles | B1: Status
A2: Giant | B2: Include
A3: Tools/Supplies | B3: Optional
A4: Distributor | B4: Alternate
A5: Employer | B5: Review
A6: Wildcard
